Workbook

Sheet Details local delivery
A1: WEEK | B1: N° Voyage | C1: Date PICK UP | D1: MOIS | E1: Matricule | F1: Chauffeur | G1: N° Voyage | H1: Delivery address | I1: Matricule | J1: Max weight truck | K1: weight | L1: Max Nbr of position truck | M1: POSITION | N1: Matricule | O1: Chauffeur | P1: ETD COF TN | Q1: Real ETD COF TN | R1: objectif ETA CLINET | S1: REAL ETA Customer | T1: Real ETD Customer | U1: ETA COFICAB | V1: real ETA COFICAB | W1: OTD | X1: kM | Y1: Stationnement | Z1: trajet allé | AA1: trajet Retour | AB1: cause | AC1: NEW OTD
B2: VOY2026COFTN01 | C2: 46024 | D2: Janvier | E2: 5735tu217 | F2: Bilel | G2: VOY2026COFTN01 | H2: ADC Sousse | I2: 5735tu217 | J2: 10200 | K2: 7100 | L2: 14 | M2: 10 | N2: 5735tu217 | O2: Bilel | P2: 0.29166667 | W2: =IFERROR(IF(S2<R2,100%,"100"%-(S2-R2)*1.2),"-") -> 1 | AC2: =IFERROR(IF(Y2<X2,100%,"100"%-(Y2-X2)*1.2),"-") -> 1
B3: VOY2026COFTN02 | C3: 46024 | D3: Janvier | E3: 4331tu175 | F3: Mehrez | G3: VOY2026COFTN02 | H3: ADC Sousse | I3: 4331tu175 | J3: 9200 | K3: 7000 | L3: 14 | M3: 10 | N3: 4331tu175 | O3: Mehrez | P3: 0.375 | W3: =IFERROR(IF(S3<R3,100%,"100"%-(S3-R3)*1.2),"-") -> 1 | AC3: =IFERROR(IF(Y3<X3,100%,"100"%-(Y3-X3)*1.2),"-") -> 1
B4: VOY2026COFTN03 | C4: 46024 | D4: Janvier | E4: 4331tu175 | F4: mehrez | G4: VOY2026COFTN03 | H4: COFAT TUNIS | I4: 4331tu175 | J4: 9200 | K4: 7000 | L4: 14 | M4: 10 | N4: 4331tu175 | O4: mehrez | P4: 0.29166667 | W4: =IFERROR(IF(S4<R4,100%,"100"%-(S4-R4)*1.2),"-") -> 1 | AC4: =IFERROR(IF(Y4<X4,100%,"100"%-(Y4-X4)*1.2),"-") -> 1
B5: VOY2026COFTN04 | C5: 46025 | D5: Janvier | E5: 4331tu175 | F5: mehrez | G5: VOY2026COFTN04 | H5: LEONI Wiring Systems Tunisia SUD | I5: 4331tu175 | J5: 9200 | K5: 7000 | L5: 14 | M5: 10 | N5: 4331tu175 | O5: mehrez | P5: 0.29166667 | W5: =IFERROR(IF(S5<R5,100%,"100"%-(S5-R5)*1.2),"-") -> 1 | AC5: =IFERROR(IF(Y5<X5,100%,"100"%-(Y5-X5)*1.2),"-") -> 1
B6: VOY2026COFTN05 | C6: 46027 | D6: Janvier | E6: REM107627 | F6: karim | G6: VOY2026COFTN05 | H6: WeWire Hammamet Tunisia SARL | I6: REM107627 | J6: 24950 | K6: 23000 | L6: 27 | M6: 10 | N6: REM107627 | O6: karim | P6: 0.41666667 | Q6: 0.31597222 | R6: 0.5 | S6: 0.375 | T6: 0.43055556 | U6: 0.47916667 | V6: 0.47916667 | W6: =IFERROR(IF(S6<R6,100%,"100"%-(S6-R6)*1.2),"-") -> 1 | AC6: =IFERROR(IF(Y6<X6,100%,"100"%-(Y6-X6)*1.2),"-") -> 1
B7: VOY2026COFTN06 | C7: 46027 | D7: Janvier | E7: REM107627 | F7: karim | G7: VOY2026COFTN06 | H7: ELECTROCONTACT TUNISIE | I7: REM107627 | J7: 24950 | K7: 22303 | L7: 27 | M7: 10 | N7: REM107627 | O7: karim | P7: 0.29166667 | Q7: 0.56597222 | R7: 0.75 | S7: 0.73958333 | T7: 0.79166667 | U7: 0.98958333 | V7: 0.98958333 | W7: =IFERROR(IF(S7<R7,100%,"100"%-(S7-R7)*1.2),"-") -> 1 | AC7: =IFERROR(IF(Y7<X7,100%,"100"%-(Y7-X7)*1.2),"-") -> 1
B8: VOY2026COFTN07 | C8: 46027 | D8: Janvier | E8: 7797tu218 | F8: Houssem | G8: VOY2026COFTN07 | H8: COFAT TUNIS | I8: 7797tu218 | J8: 927 | K8: 500 | L8: 3 | M8: 1 | N8: 7797tu218 | O8: Houssem | P8: 0.5 | W8: =IFERROR(IF(S8<R8,100%,"100"%-(S8-R8)*1.2),"-") -> 1 | AC8: =IFERROR(IF(Y8<X8,100%,"100"%-(Y8-X8)*1.2),"-") -> 1
B9: VOY2026COFTN07 | C9: 46027 | D9: Janvier | E9: Location | F9: Location | G9: VOY2026COFTN07 | H9: LEONI Wiring Systems Tunisia NORD | I9: Location | N9: SEMI REMORQUE | O9: SEMI REMORQUE | P9: 0.5 | Q9: 0.73958333 | R9: 0.5 | S9: 0.79861111 | T9: 0.86458333 | U9: 0.92708333 | V9: 0.92708333 | W9: =IFERROR(IF(S9<R9,100%,"100"%-(S9-R9)*1.2),"-") -> 0.64166667 | AB9: retard production | AC9: =IFERROR(IF(Y9<X9,100%,"100"%-(Y9-X9)*1.2),"-") -> 1
B10: VOY2026COFTN07 | C10: 46027 | D10: Janvier | E10: Location | F10: Location | G10: VOY2026COFTN07 | H10: TTE International | I10: Location | N10: SEMI REMORQUE | O10: SEMI REMORQUE | P10: 0.5 | W10: =IFERROR(IF(S10<R10,100%,"100"%-(S10-R10)*1.2),"-") -> 1 | AC10: =IFERROR(IF(Y10<X10,100%,"100"%-(Y10-X10)*1.2),"-") -> 1
B11: VOY2026COFTN08 | C11: 46027 | D11: Janvier | E11: Location | F11: Location | G11: VOY2026COFTN08 | H11: KAB-LEM Tunisia SARL | I11: Location | K11: 936 | L11: 4 | N11: SEMI REMORQUE | O11: SEMI REMORQUE | P11: 0.29166667 | W11: =IFERROR(IF(S11<R11,100%,"100"%-(S11-R11)*1.2),"-") -> 1 | AC11: =IFERROR(IF(Y11<X11,100%,"100"%-(Y11-X11)*1.2),"-") -> 1
B12: VOY2026COFTN09 | C12: 46027 | D12: Janvier | E12: 4331tu175 | F12: mehrez | G12: VOY2026COFTN09 | H12: COFAT MATEUR | I12: 4331tu175 | J12: 9200 | K12: 2100 | L12: 14 | M12: 10 | N12: 4331tu175 | O12: mehrez | P12: 0.41666667 | Q12: 0.73958333 | R12: 0.5 | S12: 0.79861111 | T12: 0.86458333 | U12: 0.92708333 | V12: 0.92708333 | W12: =IFERROR(IF(S12<R12,100%,"100"%-(S12-R12)*1.2),"-") -> 0.64166667 | AB12: retard production | AC12: =IFERROR(IF(Y12<X12,100%,"100"%-(Y12-X12)*1.2),"-") -> 1
B13: VOY2026COFTN10 | C13: 46027 | D13: Janvier | E13: 7797tu218 | F13: Houssem | G13: VOY2026COFTN10 | H13: SE BORDNETZE EL FEJJA S.A.R.L | I13: 7797tu218 | J13: 927 | K13: 500 | L13: 3 | M13: 1 | N13: 7797tu218 | O13: Houssem | P13: 0.25 | Q13: 0.46875 | R13: 0.75 | S13: 0.48958333 | T13: 0.51041667 | U13: 0.54166667 | V13: 0.54166667 | W13: =IFERROR(IF(S13<R13,100%,"100"%-(S13-R13)*1.2),"-") -> 1 | AC13: =IFERROR(IF(Y13<X13,100%,"100"%-(Y13-X13)*1.2),"-") -> 1
B14: VOY2026COFTN11 | C14: 46027 | D14: Janvier | E14: 5735tu217 | F14: Bilel | G14: VOY2026COFTN11 | H14: LEONI Wiring Systems Tunisia SUD | I14: 5735tu217 | J14: 10200 | K14: 7100 | L14: 14 | M14: 10 | N14: 5735tu217 | O14: Bilel | P14: 0.29166667 | W14: =IFERROR(IF(S14<R14,100%,"100"%-(S14-R14)*1.2),"-") -> 1 | AC14: =IFERROR(IF(Y14<X14,100%,"100"%-(Y14-X14)*1.2),"-") -> 1
B15: VOY2026COFTN12 | C15: 46027 | D15: Janvier | E15: 2282tu131 | F15: Hbib | G15: VOY2026COFTN12 | H15: YURA CORPORATION TUNISIA | I15: 2282tu131 | J15: 10200 | K15: 2810.6 | L15: 14 | M15: 10 | N15: 2282tu131 | O15: Hbib | P15: 0.5 | Q15: 0.41666667 | R15: 0.5 | S15: 0.57638889 | T15: 0.66666667 | U15: 0.82638889 | V15: 0.82638889 | W15: =IFERROR(IF(S15<R15,100%,"100"%-(S15-R15)*1.2),"-") -> 0.90833333 | AB15: retard production | AC15: =IFERROR(IF(Y15<X15,100%,"100"%-(Y15-X15)*1.2),"-") -> 1
B16: VOY2026COFTN13 | C16: 46027 | D16: Janvier | E16: 5735tu217 | F16: Bilel | G16: VOY2026COFTN13 | H16: Aptiv Services Tunisia SARL | I16: 5735tu217 | J16: 10200 | K16: 6500 | L16: 14 | M16: 10 | N16: 5735tu217 | O16: Bilel | P16: 0.41666667 | W16: =IFERROR(IF(S16<R16,100%,"100"%-(S16-R16)*1.2),"-") -> 1 | AC16: =IFERROR(IF(Y16<X16,100%,"100"%-(Y16-X16)*1.2),"-") -> 1
B17: VOY2026COFTN14 | C17: 46027 | D17: Janvier | E17: 5735tu217 | F17: Bilel | G17: VOY2026COFTN14 | H17: METS MANUFAC ELECTRO.DE SOUSSE | I17: 5735tu217 | J17: 10200 | K17: 7100 | L17: 14 | M17: 10 | N17: 5735tu217 | O17: Bilel | P17: 0.5 | W17: =IFERROR(IF(S17<R17,100%,"100"%-(S17-R17)*1.2),"-") -> 1 | AC17: =IFERROR(IF(Y17<X17,100%,"100"%-(Y17-X17)*1.2),"-") -> 1
B18: VOY2026COFTN15 | C18: 46027 | D18: Janvier | E18: 7797tu218 | F18: ala | G18: VOY2026COFTN15 | H18: Yazaki Automotive Products Tunisia | I18: 7797tu218 | J18: 927 | K18: 500 | L18: 3 | M18: 1 | N18: 7797tu218 | O18: ala | P18: 0.25 | W18: =IFERROR(IF(S18<R18,100%,"100"%-(S18-R18)*1.2),"-") -> 1 | AC18: =IFERROR(IF(Y18<X18,100%,"100"%-(Y18-X18)*1.2),"-") -> 1
B19: VOY2026COFTN16 | C19: 46027 | D19: Janvier | E19: 9524TU238 | F19: Ridha | G19: VOY2026COFTN16 | H19: SCHULTE AUTOMOTIVE TUNISIA srl | I19: 9524TU238 | J19: 10230 | K19: 10000 | L19: 14 | M19: 10 | N19: 9524TU238 | O19: Ridha | P19: 0.70833333 | Q19: 0.70833333 | R19: 0.625 | S19: 0.75 | T19: 0.70833333 | U19: 0.83333333 | V19: 0.83333333 | W19: =IFERROR(IF(S19<R19,100%,"100"%-(S19-R19)*1.2),"-") -> 0.85 | AB19: retard production | AC19: =IFERROR(IF(Y19<X19,100%,"100"%-(Y19-X19)*1.2),"-") -> 1
B20: VOY2026COFTN17 | C20: 46027 | D20: Janvier | E20: 5735tu217 | F20: bilel | G20: VOY2026COFTN17 | H20: LEONI Wiring Systems Tunisia SUD | I20: 5735tu217 | J20: 10200 | K20: 7100 | L20: 14 | M20: 10 | N20: 5735tu217 | O20: bilel | P20: 0.29166667 | Q20: 0.29166667 | R20: 0.5 | S20: 0.35416667 | T20: 0.41666667 | U20: 0.47916667 | V20: 0.47916667 | W20: =IFERROR(IF(S20<R20,100%,"100"%-(S20-R20)*1.2),"-") -> 1 | AC20: =IFERROR(IF(Y20<X20,100%,"100"%-(Y20-X20)*1.2),"-") -> 1
B21: VOY2026COFTN18 | C21: 46027 | D21: Janvier | E21: 5735tu217 | F21: bilel | G21: VOY2026COFTN18 | H21: METS MANUFAC ELECTRO.DE SOUSSE | I21: 5735tu217 | J21: 10200 | K21: 7100 | L21: 14 | M21: 10 | N21: 5735tu217 | O21: bilel | P21: 0.5 | Q21: 0.5625 | R21: 0.75 | S21: 0.63888889 | T21: 0.70833333 | U21: 0.83333333 | V21: 0.83333333 | W21: =IFERROR(IF(S21<R21,100%,"100"%-(S21-R21)*1.2),"-") -> 1 | AC21: =IFERROR(IF(Y21<X21,100%,"100"%-(Y21-X21)*1.2),"-") -> 1
B22: VOY2026COFTN19 | C22: 46028 | D22: Janvier | E22: REM107627 | F22: karim | G22: VOY2026COFTN19 | H22: LEONI Wiring Systems Tunisia NORD | I22: REM107627 | J22: 24950 | K22: 10200 | L22: 27 | M22: 14 | N22: REM107627 | O22: karim | P22: 0.29166667 | Q22: 0.46527778 | R22: 0.5 | S22: 0.55208333 | T22: 0.77083333 | U22: 0.83333333 | V22: 0.83333333 | W22: =IFERROR(IF(S22<R22,100%,"100"%-(S22-R22)*1.2),"-") -> 0.9375 | AB22: retard production | AC22: =IFERROR(IF(Y22<X22,100%,"100"%-(Y22-X22)*1.2),"-") -> 1
B23: VOY2026COFTN19 | C23: 46028 | D23: Janvier | E23: REM107627 | F23: karim | G23: VOY2026COFTN19 | H23: LEONI Wiring Systems Tunisia SUD | I23: REM107627 | J23: 24950 | K23: 10200 | L23: 27 | M23: 10 | N23: REM107627 | O23: karim | P23: 0.29166667 | Q23: 0.46527778 | R23: 0.5 | S23: 0.55208333 | T23: 0.77083333 | U23: 0.83333333 | V23: 0.83333333 | W23: =IFERROR(IF(S23<R23,100%,"100"%-(S23-R23)*1.2),"-") -> 0.9375 | AB23: retard production | AC23: =IFERROR(IF(Y23<X23,100%,"100"%-(Y23-X23)*1.2),"-") -> 1
B24: VOY2026COFTN20 | C24: 46028 | D24: Janvier | E24: 4331tu175 | F24: mehrez | G24: VOY2026COFTN20 | H24: COFAT MATEUR | I24: 4331tu175 | J24: 9200 | K24: 5500 | L24: 14 | M24: 14 | N24: 4331tu175 | O24: mehrez | P24: 0.58333333 | W24: =IFERROR(IF(S24<R24,100%,"100"%-(S24-R24)*1.2),"-") -> 1 | AC24: =IFERROR(IF(Y24<X24,100%,"100"%-(Y24-X24)*1.2),"-") -> 1
B25: VOY2026COFTN21 | C25: 46028 | D25: Janvier | E25: Location | F25: Location | G25: VOY2026COFTN21 | H25: SEBN (SUMITOMO) | I25: Location | M25: 16 | N25: SEMI REMORQUE | O25: SEMI REMORQUE | P25: 0.375 | W25: =IFERROR(IF(S25<R25,100%,"100"%-(S25-R25)*1.2),"-") -> 1 | AC25: =IFERROR(IF(Y25<X25,100%,"100"%-(Y25-X25)*1.2),"-") -> 1
B26: VOY2026COFTN21 | C26: 46028 | D26: Janvier | E26: Location | F26: Location | G26: VOY2026COFTN21 | H26: Kromberg & Schubert Tunisie SARL | I26: Location | M26: 17 | N26: SEMI REMORQUE | O26: SEMI REMORQUE | P26: 0.375 | W26: =IFERROR(IF(S26<R26,100%,"100"%-(S26-R26)*1.2),"-") -> 1 | AC26: =IFERROR(IF(Y26<X26,100%,"100"%-(Y26-X26)*1.2),"-") -> 1
B27: VOY2026COFTN22 | C27: 46028 | D27: Janvier | E27: 2282tu131 | F27: Hbib | G27: VOY2026COFTN22 | H27: Aptiv Services Tunisia SARL | I27: 2282tu131 | J27: 10200 | K27: 10200 | L27: 14 | M27: 11 | N27: 2282tu131 | O27: Hbib | P27: 0.3125 | Q27: 0.39930556 | R27: 0.75 | S27: 0.44791667 | T27: 0.49305556 | U27: 0.57291667 | V27: 0.57291667 | W27: =IFERROR(IF(S27<R27,100%,"100"%-(S27-R27)*1.2),"-") -> 1 | AC27: =IFERROR(IF(Y27<X27,100%,"100"%-(Y27-X27)*1.2),"-") -> 1
B28: VOY2026COFTN23 | C28: 46028 | D28: Janvier | E28: 2282tu131 | F28: Hbib | G28: VOY2026COFTN23 | H28: WeWire Hammamet Tunisia SARL | I28: 2282tu131 | J28: 10200 | K28: 10000 | L28: 14 | M28: 10 | N28: 2282tu131 | O28: Hbib | P28: 0.5 | Q28: 0.65972222 | R28: 0.75 | S28: 0.72916667 | T28: 0.77083333 | U28: 0.82638889 | V28: 0.82638889 | W28: =IFERROR(IF(S28<R28,100%,"100"%-(S28-R28)*1.2),"-") -> 1 | AC28: =IFERROR(IF(Y28<X28,100%,"100"%-(Y28-X28)*1.2),"-") -> 1
B29: VOY2026COFTN24 | C29: 46028 | D29: Janvier | E29: 7797tu218 | F29: Houssem | G29: VOY2026COFTN24 | H29: COFAT TUNIS | I29: 7797tu218 | J29: 927 | K29: 500 | L29: 3 | M29: 3 | N29: 7797tu218 | O29: Houssem | P29: 0.29166667 | W29: =IFERROR(IF(S29<R29,100%,"100"%-(S29-R29)*1.2),"-") -> 1 | AC29: =IFERROR(IF(Y29<X29,100%,"100"%-(Y29-X29)*1.2),"-") -> 1
B30: VOY2026COFTN25 | C30: 46028 | D30: Janvier | E30: 9524TU238 | F30: Ridha | G30: VOY2026COFTN25 | H30: perplastic | I30: 9524TU238 | J30: 10230 | K30: 10200 | L30: 14 | M30: 10 | N30: 9524TU238 | O30: Ridha | P30: 0.5 | Q30: 0.29166667 | R30: 0.5 | S30: 0.3125 | T30: 0.35416667 | U30: 0.41666667 | V30: 0.41666667 | W30: =IFERROR(IF(S30<R30,100%,"100"%-(S30-R30)*1.2),"-") -> 1 | AC30: =IFERROR(IF(Y30<X30,100%,"100"%-(Y30-X30)*1.2),"-") -> 1
B31: VOY2026COFTN26 | C31: 46028 | D31: Janvier | E31: 9524TU238 | F31: Ridha | G31: VOY2026COFTN26 | H31: SCHULTE AUTOMOTIVE TUNISIA srl | I31: 9524TU238 | J31: 10230 | K31: 10200 | L31: 14 | M31: 14 | N31: 9524TU238 | O31: Ridha | P31: 0.625 | Q31: 0.625 | W31: =IFERROR(IF(S31<R31,100%,"100"%-(S31-R31)*1.2),"-") -> 1 | AC31: =IFERROR(IF(Y31<X31,100%,"100"%-(Y31-X31)*1.2),"-") -> 1
B32: VOY2026COFTN27 | C32: 46028 | D32: Janvier | E32: 4331tu175 | F32: mehrez | G32: VOY2026COFTN27 | H32: A C T Assemblage Cable Tunisie | I32: 4331tu175 | J32: 9200 | K32: 5000 | L32: 14 | M32: 7 | N32: 4331tu175 | O32: mehrez | P32: 0.20833333 | Q32: 0.29166667 | R32: 0.5 | S32: 0.33333333 | T32: 0.41666667 | U32: 0.45833333 | V32: 0.45833333 | W32: =IFERROR(IF(S32<R32,100%,"100"%-(S32-R32)*1.2),"-") -> 1 | AC32: =IFERROR(IF(Y32<X32,100%,"100"%-(Y32-X32)*1.2),"-") -> 1
B33: VOY2026COFTN28 | C33: 46028 | D33: Janvier | E33: 4331tu175 | F33: mehrez | G33: VOY2026COFTN28 | H33: COFAT MATEUR | I33: 4331tu175 | J33: 9200 | K33: 6000 | L33: 14 | M33: 14 | N33: 4331tu175 | O33: mehrez | P33: 0.75 | Q33: 0.6875 | R33: 0.75 | S33: 0.76388889 | T33: 0.79166667 | U33: 0.875 | V33: 0.875 | W33: =IFERROR(IF(S33<R33,100%,"100"%-(S33-R33)*1.2),"-") -> 0.98333333 | AB33: retard production | AC33: =IFERROR(IF(Y33<X33,100%,"100"%-(Y33-X33)*1.2),"-") -> 1
B34: VOY2026COFTN29 | C34: 46028 | D34: Janvier | E34: Location | F34: Location | G34: VOY2026COFTN29 | H34: MEDITERRANEAN ELECTRIC WIRING | I34: Location | M34: 7 | N34: SEMI REMORQUE | O34: SEMI REMORQUE | P34: 0.29166667 | W34: =IFERROR(IF(S34<R34,100%,"100"%-(S34-R34)*1.2),"-") -> 1 | AC34: =IFERROR(IF(Y34<X34,100%,"100"%-(Y34-X34)*1.2),"-") -> 1
B35: VOY2026COFTN29 | C35: 46028 | D35: Janvier | E35: Location | F35: Location | G35: VOY2026COFTN29 | H35: YURA CORPORATION TUNISIA | I35: Location | M35: 20 | N35: SEMI REMORQUE | O35: SEMI REMORQUE | P35: 0.29166667 | W35: =IFERROR(IF(S35<R35,100%,"100"%-(S35-R35)*1.2),"-") -> 1 | AC35: =IFERROR(IF(Y35<X35,100%,"100"%-(Y35-X35)*1.2),"-") -> 1
B36: VOY2026COFTN30 | C36: 46028 | D36: Janvier | E36: 2282tu131 | F36: ala | G36: VOY2026COFTN30 | H36: COFAT MATEUR | I36: 2282tu131 | J36: 10200 | K36: 10000 | L36: 14 | M36: 10 | N36: 2282tu131 | O36: ala | P36: 0.33333333 | Q36: 0.91666667 | R36: 0.91666667 | S36: 0.5 | T36: 0.083333333 | U36: 0.19444444 | V36: 0.19444444 | W36: =IFERROR(IF(S36<R36,100%,"100"%-(S36-R36)*1.2),"-") -> 1 | AC36: =IFERROR(IF(Y36<X36,100%,"100"%-(Y36-X36)*1.2),"-") -> 1
B37: VOY2026COFTN31 | C37: 46029 | D37: Janvier | E37: 9524TU238 | F37: Ridha | G37: VOY2026COFTN31 | H37: LEONI Wiring Systems Tunisia SUD | I37: 9524TU238 | J37: 10230 | K37: 8000 | L37: 14 | M37: 11 | N37: 9524TU238 | O37: Ridha | P37: 0.29166667 | Q37: 0.38888889 | R37: 0.5 | S37: 0.45833333 | T37: 0.5 | U37: 0.58333333 | V37: 0.58333333 | W37: =IFERROR(IF(S37<R37,100%,"100"%-(S37-R37)*1.2),"-") -> 1 | AC37: =IFERROR(IF(Y37<X37,100%,"100"%-(Y37-X37)*1.2),"-") -> 1
B38: VOY2026COFTN32 | C38: 46029 | D38: Janvier | E38: 9524TU238 | F38: Ridha | G38: VOY2026COFTN32 | H38: perplastic | I38: 9524TU238 | J38: 10230 | K38: 10000 | L38: 14 | M38: 9 | N38: 9524TU238 | O38: Ridha | P38: 0.5 | Q38: 0.58333333 | R38: 0.75 | S38: 0.60416667 | T38: 0.64583333 | U38: 0.70833333 | V38: 0.70833333 | W38: =IFERROR(IF(S38<R38,100%,"100"%-(S38-R38)*1.2),"-") -> 1 | AC38: =IFERROR(IF(Y38<X38,100%,"100"%-(Y38-X38)*1.2),"-") -> 1
B39: VOY2026COFTN33 | C39: 46029 | D39: Janvier | E39: Location | F39: Location | G39: VOY2026COFTN33 | H39: SEWS TN SARL | I39: Location | M39: 7 | N39: SEMI REMORQUE | O39: SEMI REMORQUE | P39: 0.375 | W39: =IFERROR(IF(S39<R39,100%,"100"%-(S39-R39)*1.2),"-") -> 1 | AC39: =IFERROR(IF(Y39<X39,100%,"100"%-(Y39-X39)*1.2),"-") -> 1
B40: VOY2026COFTN33 | C40: 46029 | D40: Janvier | E40: Location | F40: Location | G40: VOY2026COFTN33 | H40: ELECTROCONTACT TUNISIE | I40: Location | M40: 15 | N40: SEMI REMORQUE | O40: SEMI REMORQUE | P40: 0.375 | W40: =IFERROR(IF(S40<R40,100%,"100"%-(S40-R40)*1.2),"-") -> 1 | AC40: =IFERROR(IF(Y40<X40,100%,"100"%-(Y40-X40)*1.2),"-") -> 1
...

Sheet Delivery Plan
A1: Planning de Livraison
A3: 45663 | B3: LEONI Wiring Systems Tunisia SUD | C3: 2282tu131 | D3: houssem | E3: 0.20833333
A4: 45663 | B4: LEONI Wiring Systems Tunisia Nord | C4: 2282tu131 | D4: houssem | E4: 0.20833333
A5: 45663 | B5: COFAT MATEUR | C5: 2282tu131 | D5: houssem | E5: 0.54166667
A6: 45663 | B6: Yazaki Automotive Products Tunisia | C6: 626tu203 | D6: hbib | E6: 0.20833333
A7: 45663 | B7: TTE International | C7: 626tu203 | D7: hbib | E7: 0.20833333
A8: 45663 | B8: METS MANUFAC ELECTRO.DE SOUSSE | C8: REM107627 | D8: KARIM | E8: 0.125
A9: 45663 | B9: SEWS TN SARL | C9: REM107627 | D9: KARIM | E9: 0.5
A10: 45663 | B10: ELECTROCONTACT TUNISIE | C10: 9524tu238 | D10: Ridha | E10: 0.54166667
A11: 45663 | B11: ELECTROCONTACT TUNISIE | C11: 5735tu217 | D11: bilel | E11: 0.54166667
A12: 45663 | B12: Aptiv Services Tunisia SARL | C12: 4331tu175 | D12: Mehrez | E12: 0.25
A13: 45663 | B13: WeWire Hammamet Tunisia SARL | C13: 4331tu175 | D13: Mehrez | E13: 0.41666667
A14: 45663 | B14: Perplastic TN | C14: 6502tu247 | D14: Mehrez | E14: 0.625
... A18: 45663 | B18: STE S.C.E.E.T | C18: 9524tu238 | D18: Ridha | E18: 0.25
A21: Date PICK UP | B21: Delivery address | C21: Matricule | D21: Chauffeur | E21: ETD COF TN
A22: 45665 | B22: COFAT TUNIS | C22: 5735tu217 | D22: bilel | E22: 0.29166667
A23: 45665 | B23: SCHULTE AUTOMOTIVE TUNISIA srl | C23: 5735tu217 | D23: bilel | E23: 0.41666667
A24: 45665 | B24: LEONI Wiring Systems Tunisia NORD | C24: 9524tu238 | D24: ridha | E24: 0.29166667
A25: 45665 | B25: WeWire Hammamet Tunisia SARL | C25: 2282tu131 | D25: houssem | E25: 0.5
A26: 45665 | B26: COFAT MATEUR | C26: 2282tu131 | D26: houssem | E26: 0.25
A27: 45665 | B27: LEONI Wiring Systems Tunisia SUD | C27: 2282tu131 | D27: houssem | E27: 0.25
A28: 45665 | B28: kroshu | C28: 2282tu131 | D28: houssem | E28: 0.54166667
A29: 45299 | B29: ADC SOUSSE | C29: REM107627 | D29: KARIM | E29: 0.33333333
A30: 45665 | B30: SEWS TN SARL | C30: REM107627 | D30: KARIM | E30: 0.33333333
A31: 45665 | B31: AMPHENOL | C31: 6502tu247 | D31: mehrez | E31: 0.25
A32: 45665 | B32: DIS Draxlmaier Indust Solution Gmbh | C32: 6502tu247 | D32: mehrez | E32: 0.25
A33: 45665 | B33: PERPLASTIC PVC | C33: 6502tu247 | D33: mehrez | E33: 0.54166667
... A37: 45665 | B37: kroshu | C37: vehicule | D37: barkia | E37: 0.70833333
A38: Date PICK UP | B38: Delivery address | C38: Matricule | D38: Chauffeur | E38: ETD COF TN
A39: 45666 | B39: ADC SOUSSE | C39: 5735tu217 | D39: bilel | E39: 0.20833333
A40: 45666 | B40: COFAT MATEUR | C40: 6502tu247 | D40: hbib | E40: 0.25
A41: 45666 | B41: LEONI Wiring Systems Tunisia SUD | C41: 6502tu247 | D41: hbib | E41: 0.25
A42: 45666 | B42: AMPHENOL TUNISIE | C42: 6502tu247 | D42: hbib | E42: 0.45833333
A43: 45666 | B43: Aptiv Services Tunisia SARL | C43: REM107627 | D43: KARIM | E43: 0.29166667
A44: 45666 | B44: SCHULTE AUTOMOTIVE TUNISIA srl | C44: REM107627 | D44: KARIM | E44: 0.29166667
A45: 45666 | B45: YURA CORPORATION TUNISIA | C45: 9524tu238 | D45: ridha | E45: 0.25
A46: 45666 | B46: COFAT TUNIS | C46: 2282tu131 | D46: houssem | E46: 0.29166667
A47: 45666 | B47: WeWire Hammamet Tunisia SARL | C47: 2282tu131 | D47: houssem | E47: 0.41666667
A48: 45666 | B48: I.C.eM | C48: 2282tu131 | D48: houssem | E48: 0.41666667
A49: 45666 | B49: METS MANUFAC ELECTRO.DE SOUSSE | C49: 2282tu131 | D49: houssem | E49: 0.41666667
...

Sheet RECAP Delivery Plan 
A1: N° Voyage | B1: Date de Livraison | C1: Month | D1: matricule | E1: Capacite Truck Position | F1: Nbr Position Truck | G1: Max weigh t truck | H1: Weight /Truck | I1: Stationnement | J1: otd | K1: Trajet AllE(H) | L1: Trajet Retour (H) | M1: Trajet entre les clients(H) | N1: Loading Rate % | O1: Charging Rate % | P1: Total Heure Active | Q1: Total Heure sur route | R1: Taux Occupation | S1: Loading Efficiency | T1: Km traveled | U1: ROOT CAUSE | V1: ARTICLE RETARD | W1: ACTION | X1: Frais déplacement
A2: VOY2026COFTN01 | B2: =+IFERROR(VLOOKUP(A2,'Details local delivery'!B:C,2,0),"-") -> 46024 | C2: =B2 -> 46024 | D2: =+IFERROR(VLOOKUP(A2,'Details local delivery'!B:E,4,0),"-") -> 5735tu217 | E2: =VLOOKUP(A2,'Details local delivery'!B:L,11,0) -> 14 | F2: =SUMIFS('Details local delivery'!M:M,'Details local delivery'!G:G,'RECAP Delivery Plan '!A2) -> 10 | G2: =VLOOKUP(A2,'Details local delivery'!B:J,9,0) -> 10200 | H2: =SUMIFS('Details local delivery'!K:K,'Details local delivery'!G:G,'RECAP Delivery Plan '!A2) -> 7100 | I2: =SUMIFS('Details local delivery'!Y:Y,'Details local delivery'!B:B,A:A) -> 0 | J2: =AVERAGEIFS('Details local delivery'!W:W,'Details local delivery'!B:B,A2) -> 1 | K2: =_xlfn.MAXIFS('Details local delivery'!Z:Z,'Details local delivery'!B:B,A2) -> 0 | L2: =_xlfn.MAXIFS('Details local delivery'!AA:AA,'Details local delivery'!B:B,A2) -> 0 | M2: =_xlfn.MAXIFS('Details local delivery'!AB:AB,'Details local delivery'!B:B,A2) -> 0 | N2: =+F2/E2 -> 0.71428571 | O2: =+H2/G2 -> 0.69607843 | P2: =K2+L2+M2 -> 0 | Q2: =P2+I2 -> 0 | R2: =Q2/P2 -> #DIV/0! | S2: =MAX(N2,O2) -> 0.71428571
A3: VOY2026COFTN02 | B3: =+IFERROR(VLOOKUP(A3,'Details local delivery'!B:C,2,0),"-") -> 46024 | C3: =B3 -> 46024 | D3: =+IFERROR(VLOOKUP(A3,'Details local delivery'!B:E,4,0),"-") -> 4331tu175 | E3: =VLOOKUP(A3,'Details local delivery'!B:L,11,0) -> 14 | F3: =SUMIFS('Details local delivery'!M:M,'Details local delivery'!G:G,'RECAP Delivery Plan '!A3) -> 10 | G3: =VLOOKUP(A3,'Details local delivery'!B:J,9,0) -> 9200 | H3: =SUMIFS('Details local delivery'!K:K,'Details local delivery'!G:G,'RECAP Delivery Plan '!A3) -> 7000 | I3: =SUMIFS('Details local delivery'!Y:Y,'Details local delivery'!B:B,A:A) -> 0 | J3: =AVERAGEIFS('Details local delivery'!W:W,'Details local delivery'!B:B,A3) -> 1 | K3: =_xlfn.MAXIFS('Details local delivery'!Z:Z,'Details local delivery'!B:B,A3) -> 0 | L3: =_xlfn.MAXIFS('Details local delivery'!AA:AA,'Details local delivery'!B:B,A3) -> 0 | M3: =_xlfn.MAXIFS('Details local delivery'!AB:AB,'Details local delivery'!B:B,A3) -> 0 | N3: =+F3/E3 -> 0.71428571 | O3: =+H3/G3 -> 0.76086957 | P3: =K3+L3+M3 -> 0 | Q3: =P3+I3 -> 0 | R3: =Q3/P3 -> #DIV/0! | S3: =MAX(N3,O3) -> 0.76086957
A4: VOY2026COFTN03 | B4: =+IFERROR(VLOOKUP(A4,'Details local delivery'!B:C,2,0),"-") -> 46024 | C4: =B4 -> 46024 | D4: =+IFERROR(VLOOKUP(A4,'Details local delivery'!B:E,4,0),"-") -> 4331tu175 | E4: =VLOOKUP(A4,'Details local delivery'!B:L,11,0) -> 14 | F4: =SUMIFS('Details local delivery'!M:M,'Details local delivery'!G:G,'RECAP Delivery Plan '!A4) -> 10 | G4: =VLOOKUP(A4,'Details local delivery'!B:J,9,0) -> 9200 | H4: =SUMIFS('Details local delivery'!K:K,'Details local delivery'!G:G,'RECAP Delivery Plan '!A4) -> 7000 | I4: =SUMIFS('Details local delivery'!Y:Y,'Details local delivery'!B:B,A:A) -> 0 | J4: =AVERAGEIFS('Details local delivery'!W:W,'Details local delivery'!B:B,A4) -> 1 | K4: =_xlfn.MAXIFS('Details local delivery'!Z:Z,'Details local delivery'!B:B,A4) -> 0 | L4: =_xlfn.MAXIFS('Details local delivery'!AA:AA,'Details local delivery'!B:B,A4) -> 0 | M4: =IFERROR(_xlfn.MAXIFS('Details local delivery'!AB:AB,'Details local delivery'!B:B,A4),"-") -> 0 | N4: =+F4/E4 -> 0.71428571 | O4: =+H4/G4 -> 0.76086957 | P4: =K4+L4+M4 -> 0 | Q4: =P4+I4 -> 0 | R4: =Q4/P4 -> #DIV/0! | S4: =MAX(N4,O4) -> 0.76086957
A5: VOY2026COFTN04 | B5: =+IFERROR(VLOOKUP(A5,'Details local delivery'!B:C,2,0),"-") -> 46025 | C5: =B5 -> 46025 | D5: =+IFERROR(VLOOKUP(A5,'Details local delivery'!B:E,4,0),"-") -> 4331tu175 | E5: =VLOOKUP(A5,'Details local delivery'!B:L,11,0) -> 14 | F5: =SUMIFS('Details local delivery'!M:M,'Details local delivery'!G:G,'RECAP Delivery Plan '!A5) -> 10 | G5: =VLOOKUP(A5,'Details local delivery'!B:J,9,0) -> 9200 | H5: =SUMIFS('Details local delivery'!K:K,'Details local delivery'!G:G,'RECAP Delivery Plan '!A5) -> 7000 | I5: =SUMIFS('Details local delivery'!Y:Y,'Details local delivery'!B:B,A:A) -> 0 | J5: =AVERAGEIFS('Details local delivery'!W:W,'Details local delivery'!B:B,A5) -> 1 | K5: =_xlfn.MAXIFS('Details local delivery'!Z:Z,'Details local delivery'!B:B,A5) -> 0 | L5: =_xlfn.MAXIFS('Details local delivery'!AA:AA,'Details local delivery'!B:B,A5) -> 0 | M5: =_xlfn.MAXIFS('Details local delivery'!AB:AB,'Details local delivery'!B:B,A5) -> 0 | N5: =+F5/E5 -> 0.71428571 | O5: =+H5/G5 -> 0.76086957 | P5: =K5+L5+M5 -> 0 | Q5: =P5+I5 -> 0 | R5: =Q5/P5 -> #DIV/0! | S5: =MAX(N5,O5) -> 0.76086957
A6: VOY2026COFTN05 | B6: =+IFERROR(VLOOKUP(A6,'Details local delivery'!B:C,2,0),"-") -> 46027 | C6: =B6 -> 46027 | D6: =+IFERROR(VLOOKUP(A6,'Details local delivery'!B:E,4,0),"-") -> REM107627 | E6: =VLOOKUP(A6,'Details local delivery'!B:L,11,0) -> 27 | F6: =SUMIFS('Details local delivery'!M:M,'Details local delivery'!G:G,'RECAP Delivery Plan '!A6) -> 10 | G6: =VLOOKUP(A6,'Details local delivery'!B:J,9,0) -> 24950 | H6: =SUMIFS('Details local delivery'!K:K,'Details local delivery'!G:G,'RECAP Delivery Plan '!A6) -> 23000 | I6: =SUMIFS('Details local delivery'!Y:Y,'Details local delivery'!B:B,A:A) -> 0 | J6: =AVERAGEIFS('Details local delivery'!W:W,'Details local delivery'!B:B,A6) -> 1 | K6: =_xlfn.MAXIFS('Details local delivery'!Z:Z,'Details local delivery'!B:B,A6) -> 0 | L6: =_xlfn.MAXIFS('Details local delivery'!AA:AA,'Details local delivery'!B:B,A6) -> 0 | M6: =_xlfn.MAXIFS('Details local delivery'!AB:AB,'Details local delivery'!B:B,A6) -> 0 | N6: =+F6/E6 -> 0.37037037 | O6: =+H6/G6 -> 0.92184369 | P6: =K6+L6+M6 -> 0 | Q6: =P6+I6 -> 0 | R6: =Q6/P6 -> #DIV/0! | S6: =MAX(N6,O6) -> 0.92184369
A7: VOY2026COFTN06 | B7: =+IFERROR(VLOOKUP(A7,'Details local delivery'!B:C,2,0),"-") -> 46027 | C7: =B7 -> 46027 | D7: =+IFERROR(VLOOKUP(A7,'Details local delivery'!B:E,4,0),"-") -> REM107627 | E7: =VLOOKUP(A7,'Details local delivery'!B:L,11,0) -> 27 | F7: =SUMIFS('Details local delivery'!M:M,'Details local delivery'!G:G,'RECAP Delivery Plan '!A7) -> 10 | G7: =VLOOKUP(A7,'Details local delivery'!B:J,9,0) -> 24950 | H7: =SUMIFS('Details local delivery'!K:K,'Details local delivery'!G:G,'RECAP Delivery Plan '!A7) -> 22303 | I7: =SUMIFS('Details local delivery'!Y:Y,'Details local delivery'!B:B,A:A) -> 0 | J7: =AVERAGEIFS('Details local delivery'!W:W,'Details local delivery'!B:B,A7) -> 1 | K7: =_xlfn.MAXIFS('Details local delivery'!Z:Z,'Details local delivery'!B:B,A7) -> 0 | L7: =_xlfn.MAXIFS('Details local delivery'!AA:AA,'Details local delivery'!B:B,A7) -> 0 | M7: =IFERROR(_xlfn.MAXIFS('Details local delivery'!AB:AB,'Details local delivery'!B:B,A7),"-") -> 0 | N7: =+F7/E7 -> 0.37037037 | O7: =+H7/G7 -> 0.89390782 | P7: =K7+L7+M7 -> 0 | Q7: =P7+I7 -> 0 | R7: =Q7/P7 -> #DIV/0! | S7: =MAX(N7,O7) -> 0.89390782
A8: VOY2026COFTN07 | B8: =+IFERROR(VLOOKUP(A8,'Details local delivery'!B:C,2,0),"-") -> 46027 | C8: =B8 -> 46027 | D8: =+IFERROR(VLOOKUP(A8,'Details local delivery'!B:E,4,0),"-") -> 7797tu218 | E8: =VLOOKUP(A8,'Details local delivery'!B:L,11,0) -> 3 | F8: =SUMIFS('Details local delivery'!M:M,'Details local delivery'!G:G,'RECAP Delivery Plan '!A8) -> 1 | G8: =VLOOKUP(A8,'Details local delivery'!B:J,9,0) -> 927 | H8: =SUMIFS('Details local delivery'!K:K,'Details local delivery'!G:G,'RECAP Delivery Plan '!A8) -> 500 | I8: =SUMIFS('Details local delivery'!Y:Y,'Details local delivery'!B:B,A:A) -> 0 | J8: =AVERAGEIFS('Details local delivery'!W:W,'Details local delivery'!B:B,A8) -> 0.88055556 | K8: =_xlfn.MAXIFS('Details local delivery'!Z:Z,'Details local delivery'!B:B,A8) -> 0 | L8: =_xlfn.MAXIFS('Details local delivery'!AA:AA,'Details local delivery'!B:B,A8) -> 0 | M8: =IFERROR(_xlfn.MAXIFS('Details local delivery'!AB:AB,'Details local delivery'!B:B,A8),"-") -> 0 | N8: =+F8/E8 -> 0.33333333 | O8: =+H8/G8 -> 0.53937433 | P8: =K8+L8+M8 -> 0 | Q8: =P8+I8 -> 0 | R8: =Q8/P8 -> #DIV/0! | S8: =MAX(N8,O8) -> 0.53937433
A9: VOY2026COFTN08 | B9: =+IFERROR(VLOOKUP(A9,'Details local delivery'!B:C,2,0),"-") -> 46027 | C9: =B9 -> 46027 | D9: =+IFERROR(VLOOKUP(A9,'Details local delivery'!B:E,4,0),"-") -> Location | E9: =VLOOKUP(A9,'Details local delivery'!B:L,11,0) -> 4 | F9: =SUMIFS('Details local delivery'!M:M,'Details local delivery'!G:G,'RECAP Delivery Plan '!A9) -> 0 | G9: =VLOOKUP(A9,'Details local delivery'!B:J,9,0) -> 0 | H9: =SUMIFS('Details local delivery'!K:K,'Details local delivery'!G:G,'RECAP Delivery Plan '!A9) -> 936 | I9: =SUMIFS('Details local delivery'!Y:Y,'Details local delivery'!B:B,A:A) -> 0 | J9: =AVERAGEIFS('Details local delivery'!W:W,'Details local delivery'!B:B,A9) -> 1 | K9: =_xlfn.MAXIFS('Details local delivery'!Z:Z,'Details local delivery'!B:B,A9) -> 0 | L9: =_xlfn.MAXIFS('Details local delivery'!AA:AA,'Details local delivery'!B:B,A9) -> 0 | M9: =IFERROR(_xlfn.MAXIFS('Details local delivery'!AB:AB,'Details local delivery'!B:B,A9),"-") -> 0 | N9: =+F9/E9 -> 0 | O9: =+H9/G9 -> #DIV/0! | P9: =K9+L9+M9 -> 0 | Q9: =P9+I9 -> 0 | R9: =Q9/P9 -> #DIV/0! | S9: =MAX(N9,O9) -> #DIV/0!
A10: VOY2026COFTN09 | B10: =+IFERROR(VLOOKUP(A10,'Details local delivery'!B:C,2,0),"-") -> 46027 | C10: =B10 -> 46027 | D10: =+IFERROR(VLOOKUP(A10,'Details local delivery'!B:E,4,0),"-") -> 4331tu175 | E10: =VLOOKUP(A10,'Details local delivery'!B:L,11,0) -> 14 | F10: =SUMIFS('Details local delivery'!M:M,'Details local delivery'!G:G,'RECAP Delivery Plan '!A10) -> 10 | G10: =VLOOKUP(A10,'Details local delivery'!B:J,9,0) -> 9200 | H10: =SUMIFS('Details local delivery'!K:K,'Details local delivery'!G:G,'RECAP Delivery Plan '!A10) -> 2100 | I10: =SUMIFS('Details local delivery'!Y:Y,'Details local delivery'!B:B,A:A) -> 0 | J10: =AVERAGEIFS('Details local delivery'!W:W,'Details local delivery'!B:B,A10) -> 0.64166667 | K10: =_xlfn.MAXIFS('Details local delivery'!Z:Z,'Details local delivery'!B:B,A10) -> 0 | L10: =_xlfn.MAXIFS('Details local delivery'!AA:AA,'Details local delivery'!B:B,A10) -> 0 | M10: =IFERROR(_xlfn.MAXIFS('Details local delivery'!AB:AB,'Details local delivery'!B:B,A10),"-") -> 0 | N10: =+F10/E10 -> 0.71428571 | O10: =+H10/G10 -> 0.22826087 | P10: =K10+L10+M10 -> 0 | Q10: =P10+I10 -> 0 | R10: =Q10/P10 -> #DIV/0! | S10: =MAX(N10,O10) -> 0.71428571
A11: VOY2026COFTN10 | B11: =+IFERROR(VLOOKUP(A11,'Details local delivery'!B:C,2,0),"-") -> 46027 | C11: =B11 -> 46027 | D11: =+IFERROR(VLOOKUP(A11,'Details local delivery'!B:E,4,0),"-") -> 7797tu218 | E11: =VLOOKUP(A11,'Details local delivery'!B:L,11,0) -> 3 | F11: =SUMIFS('Details local delivery'!M:M,'Details local delivery'!G:G,'RECAP Delivery Plan '!A11) -> 1 | G11: =VLOOKUP(A11,'Details local delivery'!B:J,9,0) -> 927 | H11: =SUMIFS('Details local delivery'!K:K,'Details local delivery'!G:G,'RECAP Delivery Plan '!A11) -> 500 | I11: =SUMIFS('Details local delivery'!Y:Y,'Details local delivery'!B:B,A:A) -> 0 | J11: =AVERAGEIFS('Details local delivery'!W:W,'Details local delivery'!B:B,A11) -> 1 | K11: =_xlfn.MAXIFS('Details local delivery'!Z:Z,'Details local delivery'!B:B,A11) -> 0 | L11: =_xlfn.MAXIFS('Details local delivery'!AA:AA,'Details local delivery'!B:B,A11) -> 0 | M11: =IFERROR(_xlfn.MAXIFS('Details local delivery'!AB:AB,'Details local delivery'!B:B,A11),"-") -> 0 | N11: =+F11/E11 -> 0.33333333 | O11: =+H11/G11 -> 0.53937433 | P11: =K11+L11+M11 -> 0 | Q11: =P11+I11 -> 0 | R11: =Q11/P11 -> #DIV/0! | S11: =MAX(N11,O11) -> 0.53937433
A12: VOY2026COFTN11 | B12: =+IFERROR(VLOOKUP(A12,'Details local delivery'!B:C,2,0),"-") -> 46027 | C12: =B12 -> 46027 | D12: =+IFERROR(VLOOKUP(A12,'Details local delivery'!B:E,4,0),"-") -> 5735tu217 | E12: =VLOOKUP(A12,'Details local delivery'!B:L,11,0) -> 14 | F12: =SUMIFS('Details local delivery'!M:M,'Details local delivery'!G:G,'RECAP Delivery Plan '!A12) -> 10 | G12: =VLOOKUP(A12,'Details local delivery'!B:J,9,0) -> 10200 | H12: =SUMIFS('Details local delivery'!K:K,'Details local delivery'!G:G,'RECAP Delivery Plan '!A12) -> 7100 | I12: =SUMIFS('Details local delivery'!Y:Y,'Details local delivery'!B:B,A:A) -> 0 | J12: =AVERAGEIFS('Details local delivery'!W:W,'Details local delivery'!B:B,A12) -> 1 | K12: =_xlfn.MAXIFS('Details local delivery'!Z:Z,'Details local delivery'!B:B,A12) -> 0 | L12: =_xlfn.MAXIFS('Details local delivery'!AA:AA,'Details local delivery'!B:B,A12) -> 0 | M12: =IFERROR(_xlfn.MAXIFS('Details local delivery'!AB:AB,'Details local delivery'!B:B,A12),"-") -> 0 | N12: =+F12/E12 -> 0.71428571 | O12: =+H12/G12 -> 0.69607843 | P12: =K12+L12+M12 -> 0 | Q12: =P12+I12 -> 0 | R12: =Q12/P12 -> #DIV/0! | S12: =MAX(N12,O12) -> 0.71428571
A13: VOY2026COFTN12 | B13: =+IFERROR(VLOOKUP(A13,'Details local delivery'!B:C,2,0),"-") -> 46027 | C13: =B13 -> 46027 | D13: =+IFERROR(VLOOKUP(A13,'Details local delivery'!B:E,4,0),"-") -> 2282tu131 | E13: =VLOOKUP(A13,'Details local delivery'!B:L,11,0) -> 14 | F13: =SUMIFS('Details local delivery'!M:M,'Details local delivery'!G:G,'RECAP Delivery Plan '!A13) -> 10 | G13: =VLOOKUP(A13,'Details local delivery'!B:J,9,0) -> 10200 | H13: =SUMIFS('Details local delivery'!K:K,'Details local delivery'!G:G,'RECAP Delivery Plan '!A13) -> 2810.6 | I13: =SUMIFS('Details local delivery'!Y:Y,'Details local delivery'!B:B,A:A) -> 0 | J13: =AVERAGEIFS('Details local delivery'!W:W,'Details local delivery'!B:B,A13) -> 0.90833333 | K13: =_xlfn.MAXIFS('Details local delivery'!Z:Z,'Details local delivery'!B:B,A13) -> 0 | L13: =_xlfn.MAXIFS('Details local delivery'!AA:AA,'Details local delivery'!B:B,A13) -> 0 | M13: =IFERROR(_xlfn.MAXIFS('Details local delivery'!AB:AB,'Details local delivery'!B:B,A13),"-") -> 0 | N13: =+F13/E13 -> 0.71428571 | O13: =+H13/G13 -> 0.27554902 | P13: =K13+L13+M13 -> 0 | Q13: =P13+I13 -> 0 | R13: =Q13/P13 -> #DIV/0! | S13: =MAX(N13,O13) -> 0.71428571
A14: VOY2026COFTN13 | B14: =+IFERROR(VLOOKUP(A14,'Details local delivery'!B:C,2,0),"-") -> 46027 | C14: =B14 -> 46027 | D14: =+IFERROR(VLOOKUP(A14,'Details local delivery'!B:E,4,0),"-") -> 5735tu217 | E14: =VLOOKUP(A14,'Details local delivery'!B:L,11,0) -> 14 | F14: =SUMIFS('Details local delivery'!M:M,'Details local delivery'!G:G,'RECAP Delivery Plan '!A14) -> 10 | G14: =VLOOKUP(A14,'Details local delivery'!B:J,9,0) -> 10200 | H14: =SUMIFS('Details local delivery'!K:K,'Details local delivery'!G:G,'RECAP Delivery Plan '!A14) -> 6500 | I14: =SUMIFS('Details local delivery'!Y:Y,'Details local delivery'!B:B,A:A) -> 0 | J14: =AVERAGEIFS('Details local delivery'!W:W,'Details local delivery'!B:B,A14) -> 1 | K14: =_xlfn.MAXIFS('Details local delivery'!Z:Z,'Details local delivery'!B:B,A14) -> 0 | L14: =_xlfn.MAXIFS('Details local delivery'!AA:AA,'Details local delivery'!B:B,A14) -> 0 | M14: =IFERROR(_xlfn.MAXIFS('Details local delivery'!AB:AB,'Details local delivery'!B:B,A14),"-") -> 0 | N14: =+F14/E14 -> 0.71428571 | O14: =+H14/G14 -> 0.6372549 | P14: =K14+L14+M14 -> 0 | Q14: =P14+I14 -> 0 | R14: =Q14/P14 -> #DIV/0! | S14: =MAX(N14,O14) -> 0.71428571
A15: VOY2026COFTN14 | B15: =+IFERROR(VLOOKUP(A15,'Details local delivery'!B:C,2,0),"-") -> 46027 | C15: =B15 -> 46027 | D15: =+IFERROR(VLOOKUP(A15,'Details local delivery'!B:E,4,0),"-") -> 5735tu217 | E15: =VLOOKUP(A15,'Details local delivery'!B:L,11,0) -> 14 | F15: =SUMIFS('Details local delivery'!M:M,'Details local delivery'!G:G,'RECAP Delivery Plan '!A15) -> 10 | G15: =VLOOKUP(A15,'Details local delivery'!B:J,9,0) -> 10200 | H15: =SUMIFS('Details local delivery'!K:K,'Details local delivery'!G:G,'RECAP Delivery Plan '!A15) -> 7100 | I15: =SUMIFS('Details local delivery'!Y:Y,'Details local delivery'!B:B,A:A) -> 0 | J15: =AVERAGEIFS('Details local delivery'!W:W,'Details local delivery'!B:B,A15) -> 1 | K15: =_xlfn.MAXIFS('Details local delivery'!Z:Z,'Details local delivery'!B:B,A15) -> 0 | L15: =_xlfn.MAXIFS('Details local delivery'!AA:AA,'Details local delivery'!B:B,A15) -> 0 | M15: =IFERROR(_xlfn.MAXIFS('Details local delivery'!AB:AB,'Details local delivery'!B:B,A15),"-") -> 0 | N15: =+F15/E15 -> 0.71428571 | O15: =+H15/G15 -> 0.69607843 | P15: =K15+L15+M15 -> 0 | Q15: =P15+I15 -> 0 | R15: =Q15/P15 -> #DIV/0! | S15: =MAX(N15,O15) -> 0.71428571
A16: VOY2026COFTN15 | B16: =+IFERROR(VLOOKUP(A16,'Details local delivery'!B:C,2,0),"-") -> 46027 | C16: =B16 -> 46027 | D16: =+IFERROR(VLOOKUP(A16,'Details local delivery'!B:E,4,0),"-") -> 7797tu218 | E16: =VLOOKUP(A16,'Details local delivery'!B:L,11,0) -> 3 | F16: =SUMIFS('Details local delivery'!M:M,'Details local delivery'!G:G,'RECAP Delivery Plan '!A16) -> 1 | G16: =VLOOKUP(A16,'Details local delivery'!B:J,9,0) -> 927 | H16: =SUMIFS('Details local delivery'!K:K,'Details local delivery'!G:G,'RECAP Delivery Plan '!A16) -> 500 | I16: =SUMIFS('Details local delivery'!Y:Y,'Details local delivery'!B:B,A:A) -> 0 | J16: =AVERAGEIFS('Details local delivery'!W:W,'Details local delivery'!B:B,A16) -> 1 | K16: =_xlfn.MAXIFS('Details local delivery'!Z:Z,'Details local delivery'!B:B,A16) -> 0 | L16: =_xlfn.MAXIFS('Details local delivery'!AA:AA,'Details local delivery'!B:B,A16) -> 0 | M16: =_xlfn.MAXIFS('Details local delivery'!AB:AB,'Details local delivery'!B:B,A16) -> 0 | N16: =+F16/E16 -> 0.33333333 | O16: =+H16/G16 -> 0.53937433 | P16: =K16+L16+M16 -> 0 | Q16: =P16+I16 -> 0 | R16: =Q16/P16 -> #DIV/0! | S16: =MAX(N16,O16) -> 0.53937433
A17: VOY2026COFTN16 | B17: =+IFERROR(VLOOKUP(A17,'Details local delivery'!B:C,2,0),"-") -> 46027 | C17: =B17 -> 46027 | D17: =+IFERROR(VLOOKUP(A17,'Details local delivery'!B:E,4,0),"-") -> 9524TU238 | E17: =VLOOKUP(A17,'Details local delivery'!B:L,11,0) -> 14 | F17: =SUMIFS('Details local delivery'!M:M,'Details local delivery'!G:G,'RECAP Delivery Plan '!A17) -> 10 | G17: =VLOOKUP(A17,'Details local delivery'!B:J,9,0) -> 10230 | H17: =SUMIFS('Details local delivery'!K:K,'Details local delivery'!G:G,'RECAP Delivery Plan '!A17) -> 10000 | I17: =SUMIFS('Details local delivery'!Y:Y,'Details local delivery'!B:B,A:A) -> 0 | J17: =AVERAGEIFS('Details local delivery'!W:W,'Details local delivery'!B:B,A17) -> 0.85 | K17: =_xlfn.MAXIFS('Details local delivery'!Z:Z,'Details local delivery'!B:B,A17) -> 0 | L17: =_xlfn.MAXIFS('Details local delivery'!AA:AA,'Details local delivery'!B:B,A17) -> 0 | M17: =_xlfn.MAXIFS('Details local delivery'!AB:AB,'Details local delivery'!B:B,A17) -> 0 | N17: =+F17/E17 -> 0.71428571 | O17: =+H17/G17 -> 0.97751711 | P17: =K17+L17+M17 -> 0 | Q17: =P17+I17 -> 0 | R17: =Q17/P17 -> #DIV/0! | S17: =MAX(N17,O17) -> 0.97751711
A18: VOY2026COFTN17 | B18: =+IFERROR(VLOOKUP(A18,'Details local delivery'!B:C,2,0),"-") -> 46027 | C18: =B18 -> 46027 | D18: =+IFERROR(VLOOKUP(A18,'Details local delivery'!B:E,4,0),"-") -> 5735tu217 | E18: =VLOOKUP(A18,'Details local delivery'!B:L,11,0) -> 14 | F18: =SUMIFS('Details local delivery'!M:M,'Details local delivery'!G:G,'RECAP Delivery Plan '!A18) -> 10 | G18: =VLOOKUP(A18,'Details local delivery'!B:J,9,0) -> 10200 | H18: =SUMIFS('Details local delivery'!K:K,'Details local delivery'!G:G,'RECAP Delivery Plan '!A18) -> 7100 | I18: =SUMIFS('Details local delivery'!Y:Y,'Details local delivery'!B:B,A:A) -> 0 | J18: =AVERAGEIFS('Details local delivery'!W:W,'Details local delivery'!B:B,A18) -> 1 | K18: =_xlfn.MAXIFS('Details local delivery'!Z:Z,'Details local delivery'!B:B,A18) -> 0 | L18: =_xlfn.MAXIFS('Details local delivery'!AA:AA,'Details local delivery'!B:B,A18) -> 0 | M18: =IFERROR(_xlfn.MAXIFS('Details local delivery'!AB:AB,'Details local delivery'!B:B,A18),"-") -> 0 | N18: =+F18/E18 -> 0.71428571 | O18: =+H18/G18 -> 0.69607843 | P18: =K18+L18+M18 -> 0 | Q18: =P18+I18 -> 0 | R18: =Q18/P18 -> #DIV/0! | S18: =MAX(N18,O18) -> 0.71428571
A19: VOY2026COFTN18 | B19: =+IFERROR(VLOOKUP(A19,'Details local delivery'!B:C,2,0),"-") -> 46027 | C19: =B19 -> 46027 | D19: =+IFERROR(VLOOKUP(A19,'Details local delivery'!B:E,4,0),"-") -> 5735tu217 | E19: =VLOOKUP(A19,'Details local delivery'!B:L,11,0) -> 14 | F19: =SUMIFS('Details local delivery'!M:M,'Details local delivery'!G:G,'RECAP Delivery Plan '!A19) -> 10 | G19: =VLOOKUP(A19,'Details local delivery'!B:J,9,0) -> 10200 | H19: =SUMIFS('Details local delivery'!K:K,'Details local delivery'!G:G,'RECAP Delivery Plan '!A19) -> 7100 | I19: =SUMIFS('Details local delivery'!Y:Y,'Details local delivery'!B:B,A:A) -> 0 | J19: =AVERAGEIFS('Details local delivery'!W:W,'Details local delivery'!B:B,A19) -> 1 | K19: =_xlfn.MAXIFS('Details local delivery'!Z:Z,'Details local delivery'!B:B,A19) -> 0 | L19: =_xlfn.MAXIFS('Details local delivery'!AA:AA,'Details local delivery'!B:B,A19) -> 0 | M19: =_xlfn.MAXIFS('Details local delivery'!AB:AB,'Details local delivery'!B:B,A19) -> 0 | N19: =+F19/E19 -> 0.71428571 | O19: =+H19/G19 -> 0.69607843 | P19: =K19+L19+M19 -> 0 | Q19: =P19+I19 -> 0 | R19: =Q19/P19 -> #DIV/0! | S19: =MAX(N19,O19) -> 0.71428571
A20: VOY2026COFTN19 | B20: =+IFERROR(VLOOKUP(A20,'Details local delivery'!B:C,2,0),"-") -> 46028 | C20: =B20 -> 46028 | D20: =+IFERROR(VLOOKUP(A20,'Details local delivery'!B:E,4,0),"-") -> REM107627 | E20: =VLOOKUP(A20,'Details local delivery'!B:L,11,0) -> 27 | F20: =SUMIFS('Details local delivery'!M:M,'Details local delivery'!G:G,'RECAP Delivery Plan '!A20) -> 24 | G20: =VLOOKUP(A20,'Details local delivery'!B:J,9,0) -> 24950 | H20: =SUMIFS('Details local delivery'!K:K,'Details local delivery'!G:G,'RECAP Delivery Plan '!A20) -> 20400 | I20: =SUMIFS('Details local delivery'!Y:Y,'Details local delivery'!B:B,A:A) -> 0 | J20: =AVERAGEIFS('Details local delivery'!W:W,'Details local delivery'!B:B,A20) -> 0.9375 | K20: =_xlfn.MAXIFS('Details local delivery'!Z:Z,'Details local delivery'!B:B,A20) -> 0 | L20: =_xlfn.MAXIFS('Details local delivery'!AA:AA,'Details local delivery'!B:B,A20) -> 0 | M20: =IFERROR(_xlfn.MAXIFS('Details local delivery'!AB:AB,'Details local delivery'!B:B,A20),"-") -> 0 | N20: =+F20/E20 -> 0.88888889 | O20: =+H20/G20 -> 0.81763527 | P20: =K20+L20+M20 -> 0 | Q20: =P20+I20 -> 0 | R20: =Q20/P20 -> #DIV/0! | S20: =MAX(N20,O20) -> 0.88888889
A21: VOY2026COFTN20 | B21: =+IFERROR(VLOOKUP(A21,'Details local delivery'!B:C,2,0),"-") -> 46028 | C21: =B21 -> 46028 | D21: =+IFERROR(VLOOKUP(A21,'Details local delivery'!B:E,4,0),"-") -> 4331tu175 | E21: =VLOOKUP(A21,'Details local delivery'!B:L,11,0) -> 14 | F21: =SUMIFS('Details local delivery'!M:M,'Details local delivery'!G:G,'RECAP Delivery Plan '!A21) -> 14 | G21: =VLOOKUP(A21,'Details local delivery'!B:J,9,0) -> 9200 | H21: =SUMIFS('Details local delivery'!K:K,'Details local delivery'!G:G,'RECAP Delivery Plan '!A21) -> 5500 | I21: =SUMIFS('Details local delivery'!Y:Y,'Details local delivery'!B:B,A:A) -> 0 | J21: =AVERAGEIFS('Details local delivery'!W:W,'Details local delivery'!B:B,A21) -> 1 | K21: =_xlfn.MAXIFS('Details local delivery'!Z:Z,'Details local delivery'!B:B,A21) -> 0 | L21: =_xlfn.MAXIFS('Details local delivery'!AA:AA,'Details local delivery'!B:B,A21) -> 0 | M21: =IFERROR(_xlfn.MAXIFS('Details local delivery'!AB:AB,'Details local delivery'!B:B,A21),"-") -> 0 | N21: =+F21/E21 -> 1 | O21: =+H21/G21 -> 0.59782609 | P21: =K21+L21+M21 -> 0 | Q21: =P21+I21 -> 0 | R21: =Q21/P21 -> #DIV/0! | S21: =MAX(N21,O21) -> 1
A22: VOY2026COFTN21 | B22: =+IFERROR(VLOOKUP(A22,'Details local delivery'!B:C,2,0),"-") -> 46028 | C22: =B22 -> 46028 | D22: =+IFERROR(VLOOKUP(A22,'Details local delivery'!B:E,4,0),"-") -> Location | E22: =VLOOKUP(A22,'Details local delivery'!B:L,11,0) -> 0 | F22: =SUMIFS('Details local delivery'!M:M,'Details local delivery'!G:G,'RECAP Delivery Plan '!A22) -> 33 | G22: =VLOOKUP(A22,'Details local delivery'!B:J,9,0) -> 0 | H22: =SUMIFS('Details local delivery'!K:K,'Details local delivery'!G:G,'RECAP Delivery Plan '!A22) -> 0 | I22: =SUMIFS('Details local delivery'!Y:Y,'Details local delivery'!B:B,A:A) -> 0 | J22: =AVERAGEIFS('Details local delivery'!W:W,'Details local delivery'!B:B,A22) -> 1 | K22: =_xlfn.MAXIFS('Details local delivery'!Z:Z,'Details local delivery'!B:B,A22) -> 0 | L22: =_xlfn.MAXIFS('Details local delivery'!AA:AA,'Details local delivery'!B:B,A22) -> 0 | M22: =IFERROR(_xlfn.MAXIFS('Details local delivery'!AB:AB,'Details local delivery'!B:B,A22),"-") -> 0 | N22: =+F22/E22 -> #DIV/0! | O22: =+H22/G22 -> #DIV/0! | P22: =K22+L22+M22 -> 0 | Q22: =P22+I22 -> 0 | R22: =Q22/P22 -> #DIV/0! | S22: =MAX(N22,O22) -> #DIV/0!
A23: VOY2026COFTN22 | B23: =+IFERROR(VLOOKUP(A23,'Details local delivery'!B:C,2,0),"-") -> 46028 | C23: =B23 -> 46028 | D23: =+IFERROR(VLOOKUP(A23,'Details local delivery'!B:E,4,0),"-") -> 2282tu131 | E23: =VLOOKUP(A23,'Details local delivery'!B:L,11,0) -> 14 | F23: =SUMIFS('Details local delivery'!M:M,'Details local delivery'!G:G,'RECAP Delivery Plan '!A23) -> 11 | G23: =VLOOKUP(A23,'Details local delivery'!B:J,9,0) -> 10200 | H23: =SUMIFS('Details local delivery'!K:K,'Details local delivery'!G:G,'RECAP Delivery Plan '!A23) -> 10200 | I23: =SUMIFS('Details local delivery'!Y:Y,'Details local delivery'!B:B,A:A) -> 0 | J23: =AVERAGEIFS('Details local delivery'!W:W,'Details local delivery'!B:B,A23) -> 1 | K23: =_xlfn.MAXIFS('Details local delivery'!Z:Z,'Details local delivery'!B:B,A23) -> 0 | L23: =_xlfn.MAXIFS('Details local delivery'!AA:AA,'Details local delivery'!B:B,A23) -> 0 | M23: =IFERROR(_xlfn.MAXIFS('Details local delivery'!AB:AB,'Details local delivery'!B:B,A23),"-") -> 0 | N23: =+F23/E23 -> 0.78571429 | O23: =+H23/G23 -> 1 | P23: =K23+L23+M23 -> 0 | Q23: =P23+I23 -> 0 | R23: =Q23/P23 -> #DIV/0! | S23: =MAX(N23,O23) -> 1
A24: VOY2026COFTN23 | B24: =+IFERROR(VLOOKUP(A24,'Details local delivery'!B:C,2,0),"-") -> 46028 | C24: =B24 -> 46028 | D24: =+IFERROR(VLOOKUP(A24,'Details local delivery'!B:E,4,0),"-") -> 2282tu131 | E24: =VLOOKUP(A24,'Details local delivery'!B:L,11,0) -> 14 | F24: =SUMIFS('Details local delivery'!M:M,'Details local delivery'!G:G,'RECAP Delivery Plan '!A24) -> 10 | G24: =VLOOKUP(A24,'Details local delivery'!B:J,9,0) -> 10200 | H24: =SUMIFS('Details local delivery'!K:K,'Details local delivery'!G:G,'RECAP Delivery Plan '!A24) -> 10000 | I24: =SUMIFS('Details local delivery'!Y:Y,'Details local delivery'!B:B,A:A) -> 0 | J24: =AVERAGEIFS('Details local delivery'!W:W,'Details local delivery'!B:B,A24) -> 1 | K24: =_xlfn.MAXIFS('Details local delivery'!Z:Z,'Details local delivery'!B:B,A24) -> 0 | L24: =_xlfn.MAXIFS('Details local delivery'!AA:AA,'Details local delivery'!B:B,A24) -> 0 | M24: =_xlfn.MAXIFS('Details local delivery'!AB:AB,'Details local delivery'!B:B,A24) -> 0 | N24: =+F24/E24 -> 0.71428571 | O24: =+H24/G24 -> 0.98039216 | P24: =K24+L24+M24 -> 0 | Q24: =P24+I24 -> 0 | R24: =Q24/P24 -> #DIV/0! | S24: =MAX(N24,O24) -> 0.98039216
A25: VOY2026COFTN24 | B25: =+IFERROR(VLOOKUP(A25,'Details local delivery'!B:C,2,0),"-") -> 46028 | C25: =B25 -> 46028 | D25: =+IFERROR(VLOOKUP(A25,'Details local delivery'!B:E,4,0),"-") -> 7797tu218 | E25: =VLOOKUP(A25,'Details local delivery'!B:L,11,0) -> 3 | F25: =SUMIFS('Details local delivery'!M:M,'Details local delivery'!G:G,'RECAP Delivery Plan '!A25) -> 3 | G25: =VLOOKUP(A25,'Details local delivery'!B:J,9,0) -> 927 | H25: =SUMIFS('Details local delivery'!K:K,'Details local delivery'!G:G,'RECAP Delivery Plan '!A25) -> 500 | I25: =SUMIFS('Details local delivery'!Y:Y,'Details local delivery'!B:B,A:A) -> 0 | J25: =AVERAGEIFS('Details local delivery'!W:W,'Details local delivery'!B:B,A25) -> 1 | K25: =_xlfn.MAXIFS('Details local delivery'!Z:Z,'Details local delivery'!B:B,A25) -> 0 | L25: =_xlfn.MAXIFS('Details local delivery'!AA:AA,'Details local delivery'!B:B,A25) -> 0 | M25: =IFERROR(_xlfn.MAXIFS('Details local delivery'!AB:AB,'Details local delivery'!B:B,A25),"-") -> 0 | N25: =+F25/E25 -> 1 | O25: =+H25/G25 -> 0.53937433 | P25: =K25+L25+M25 -> 0 | Q25: =P25+I25 -> 0 | R25: =Q25/P25 -> #DIV/0! | S25: =MAX(N25,O25) -> 1
A26: VOY2026COFTN25 | B26: =+IFERROR(VLOOKUP(A26,'Details local delivery'!B:C,2,0),"-") -> 46028 | C26: =B26 -> 46028 | D26: =+IFERROR(VLOOKUP(A26,'Details local delivery'!B:E,4,0),"-") -> 9524TU238 | E26: =VLOOKUP(A26,'Details local delivery'!B:L,11,0) -> 14 | F26: =SUMIFS('Details local delivery'!M:M,'Details local delivery'!G:G,'RECAP Delivery Plan '!A26) -> 10 | G26: =VLOOKUP(A26,'Details local delivery'!B:J,9,0) -> 10230 | H26: =SUMIFS('Details local delivery'!K:K,'Details local delivery'!G:G,'RECAP Delivery Plan '!A26) -> 10200 | I26: =SUMIFS('Details local delivery'!Y:Y,'Details local delivery'!B:B,A:A) -> 0 | J26: =AVERAGEIFS('Details local delivery'!W:W,'Details local delivery'!B:B,A26) -> 1 | K26: =_xlfn.MAXIFS('Details local delivery'!Z:Z,'Details local delivery'!B:B,A26) -> 0 | L26: =_xlfn.MAXIFS('Details local delivery'!AA:AA,'Details local delivery'!B:B,A26) -> 0 | M26: =IFERROR(_xlfn.MAXIFS('Details local delivery'!AB:AB,'Details local delivery'!B:B,A26),"-") -> 0 | N26: =+F26/E26 -> 0.71428571 | O26: =+H26/G26 -> 0.99706745 | P26: =K26+L26+M26 -> 0 | Q26: =P26+I26 -> 0 | R26: =Q26/P26 -> #DIV/0! | S26: =MAX(N26,O26) -> 0.99706745
A27: VOY2026COFTN26 | B27: =+IFERROR(VLOOKUP(A27,'Details local delivery'!B:C,2,0),"-") -> 46028 | C27: =B27 -> 46028 | D27: =+IFERROR(VLOOKUP(A27,'Details local delivery'!B:E,4,0),"-") -> 9524TU238 | E27: =VLOOKUP(A27,'Details local delivery'!B:L,11,0) -> 14 | F27: =SUMIFS('Details local delivery'!M:M,'Details local delivery'!G:G,'RECAP Delivery Plan '!A27) -> 14 | G27: =VLOOKUP(A27,'Details local delivery'!B:J,9,0) -> 10230 | H27: =SUMIFS('Details local delivery'!K:K,'Details local delivery'!G:G,'RECAP Delivery Plan '!A27) -> 10200 | I27: =SUMIFS('Details local delivery'!Y:Y,'Details local delivery'!B:B,A:A) -> 0 | J27: =AVERAGEIFS('Details local delivery'!W:W,'Details local delivery'!B:B,A27) -> 1 | K27: =_xlfn.MAXIFS('Details local delivery'!Z:Z,'Details local delivery'!B:B,A27) -> 0 | L27: =_xlfn.MAXIFS('Details local delivery'!AA:AA,'Details local delivery'!B:B,A27) -> 0 | M27: =IFERROR(_xlfn.MAXIFS('Details local delivery'!AB:AB,'Details local delivery'!B:B,A27),"-") -> 0 | N27: =+F27/E27 -> 1 | O27: =+H27/G27 -> 0.99706745 | P27: =K27+L27+M27 -> 0 | Q27: =P27+I27 -> 0 | R27: =Q27/P27 -> #DIV/0! | S27: =MAX(N27,O27) -> 1
A28: VOY2026COFTN27 | B28: =+IFERROR(VLOOKUP(A28,'Details local delivery'!B:C,2,0),"-") -> 46028 | C28: =B28 -> 46028 | D28: =+IFERROR(VLOOKUP(A28,'Details local delivery'!B:E,4,0),"-") -> 4331tu175 | E28: =VLOOKUP(A28,'Details local delivery'!B:L,11,0) -> 14 | F28: =SUMIFS('Details local delivery'!M:M,'Details local delivery'!G:G,'RECAP Delivery Plan '!A28) -> 7 | G28: =VLOOKUP(A28,'Details local delivery'!B:J,9,0) -> 9200 | H28: =SUMIFS('Details local delivery'!K:K,'Details local delivery'!G:G,'RECAP Delivery Plan '!A28) -> 5000 | I28: =SUMIFS('Details local delivery'!Y:Y,'Details local delivery'!B:B,A:A) -> 0 | J28: =AVERAGEIFS('Details local delivery'!W:W,'Details local delivery'!B:B,A28) -> 1 | K28: =_xlfn.MAXIFS('Details local delivery'!Z:Z,'Details local delivery'!B:B,A28) -> 0 | L28: =_xlfn.MAXIFS('Details local delivery'!AA:AA,'Details local delivery'!B:B,A28) -> 0 | M28: =_xlfn.MAXIFS('Details local delivery'!AB:AB,'Details local delivery'!B:B,A28) -> 0 | N28: =+F28/E28 -> 0.5 | O28: =+H28/G28 -> 0.54347826 | P28: =K28+L28+M28 -> 0 | Q28: =P28+I28 -> 0 | R28: =Q28/P28 -> #DIV/0! | S28: =MAX(N28,O28) -> 0.54347826
A29: VOY2026COFTN28 | B29: =+IFERROR(VLOOKUP(A29,'Details local delivery'!B:C,2,0),"-") -> 46028 | C29: =B29 -> 46028 | D29: =+IFERROR(VLOOKUP(A29,'Details local delivery'!B:E,4,0),"-") -> 4331tu175 | E29: =VLOOKUP(A29,'Details local delivery'!B:L,11,0) -> 14 | F29: =SUMIFS('Details local delivery'!M:M,'Details local delivery'!G:G,'RECAP Delivery Plan '!A29) -> 14 | G29: =VLOOKUP(A29,'Details local delivery'!B:J,9,0) -> 9200 | H29: =SUMIFS('Details local delivery'!K:K,'Details local delivery'!G:G,'RECAP Delivery Plan '!A29) -> 6000 | I29: =SUMIFS('Details local delivery'!Y:Y,'Details local delivery'!B:B,A:A) -> 0 | J29: =AVERAGEIFS('Details local delivery'!W:W,'Details local delivery'!B:B,A29) -> 0.98333333 | K29: =_xlfn.MAXIFS('Details local delivery'!Z:Z,'Details local delivery'!B:B,A29) -> 0 | L29: =_xlfn.MAXIFS('Details local delivery'!AA:AA,'Details local delivery'!B:B,A29) -> 0 | M29: =_xlfn.MAXIFS('Details local delivery'!AB:AB,'Details local delivery'!B:B,A29) -> 0 | N29: =+F29/E29 -> 1 | O29: =+H29/G29 -> 0.65217391 | P29: =K29+L29+M29 -> 0 | Q29: =P29+I29 -> 0 | R29: =Q29/P29 -> #DIV/0! | S29: =MAX(N29,O29) -> 1
A30: VOY2026COFTN29 | B30: =+IFERROR(VLOOKUP(A30,'Details local delivery'!B:C,2,0),"-") -> 46028 | C30: =B30 -> 46028 | D30: =+IFERROR(VLOOKUP(A30,'Details local delivery'!B:E,4,0),"-") -> Location | E30: =VLOOKUP(A30,'Details local delivery'!B:L,11,0) -> 0 | F30: =SUMIFS('Details local delivery'!M:M,'Details local delivery'!G:G,'RECAP Delivery Plan '!A30) -> 27 | G30: =VLOOKUP(A30,'Details local delivery'!B:J,9,0) -> 0 | H30: =SUMIFS('Details local delivery'!K:K,'Details local delivery'!G:G,'RECAP Delivery Plan '!A30) -> 0 | I30: =SUMIFS('Details local delivery'!Y:Y,'Details local delivery'!B:B,A:A) -> 0 | J30: =AVERAGEIFS('Details local delivery'!W:W,'Details local delivery'!B:B,A30) -> 1 | K30: =_xlfn.MAXIFS('Details local delivery'!Z:Z,'Details local delivery'!B:B,A30) -> 0 | L30: =_xlfn.MAXIFS('Details local delivery'!AA:AA,'Details local delivery'!B:B,A30) -> 0 | M30: =_xlfn.MAXIFS('Details local delivery'!AB:AB,'Details local delivery'!B:B,A30) -> 0 | N30: =+F30/E30 -> #DIV/0! | O30: =+H30/G30 -> #DIV/0! | P30: =K30+L30+M30 -> 0 | Q30: =P30+I30 -> 0 | R30: =Q30/P30 -> #DIV/0! | S30: =MAX(N30,O30) -> #DIV/0!
A31: VOY2026COFTN30 | B31: =+IFERROR(VLOOKUP(A31,'Details local delivery'!B:C,2,0),"-") -> 46028 | C31: =B31 -> 46028 | D31: =+IFERROR(VLOOKUP(A31,'Details local delivery'!B:E,4,0),"-") -> 2282tu131 | E31: =VLOOKUP(A31,'Details local delivery'!B:L,11,0) -> 14 | F31: =SUMIFS('Details local delivery'!M:M,'Details local delivery'!G:G,'RECAP Delivery Plan '!A31) -> 10 | G31: =VLOOKUP(A31,'Details local delivery'!B:J,9,0) -> 10200 | H31: =SUMIFS('Details local delivery'!K:K,'Details local delivery'!G:G,'RECAP Delivery Plan '!A31) -> 10000 | I31: =SUMIFS('Details local delivery'!Y:Y,'Details local delivery'!B:B,A:A) -> 0 | J31: =AVERAGEIFS('Details local delivery'!W:W,'Details local delivery'!B:B,A31) -> 1 | K31: =_xlfn.MAXIFS('Details local delivery'!Z:Z,'Details local delivery'!B:B,A31) -> 0 | L31: =_xlfn.MAXIFS('Details local delivery'!AA:AA,'Details local delivery'!B:B,A31) -> 0 | M31: =_xlfn.MAXIFS('Details local delivery'!AB:AB,'Details local delivery'!B:B,A31) -> 0 | N31: =+F31/E31 -> 0.71428571 | O31: =+H31/G31 -> 0.98039216 | P31: =K31+L31+M31 -> 0 | Q31: =P31+I31 -> 0 | R31: =Q31/P31 -> #DIV/0! | S31: =MAX(N31,O31) -> 0.98039216
A32: VOY2026COFTN31 | B32: =+IFERROR(VLOOKUP(A32,'Details local delivery'!B:C,2,0),"-") -> 46029 | C32: =B32 -> 46029 | D32: =+IFERROR(VLOOKUP(A32,'Details local delivery'!B:E,4,0),"-") -> 9524TU238 | E32: =VLOOKUP(A32,'Details local delivery'!B:L,11,0) -> 14 | F32: =SUMIFS('Details local delivery'!M:M,'Details local delivery'!G:G,'RECAP Delivery Plan '!A32) -> 11 | G32: =VLOOKUP(A32,'Details local delivery'!B:J,9,0) -> 10230 | H32: =SUMIFS('Details local delivery'!K:K,'Details local delivery'!G:G,'RECAP Delivery Plan '!A32) -> 8000 | I32: =SUMIFS('Details local delivery'!Y:Y,'Details local delivery'!B:B,A:A) -> 0 | J32: =AVERAGEIFS('Details local delivery'!W:W,'Details local delivery'!B:B,A32) -> 1 | K32: =_xlfn.MAXIFS('Details local delivery'!Z:Z,'Details local delivery'!B:B,A32) -> 0 | L32: =_xlfn.MAXIFS('Details local delivery'!AA:AA,'Details local delivery'!B:B,A32) -> 0 | M32: =IFERROR(_xlfn.MAXIFS('Details local delivery'!AB:AB,'Details local delivery'!B:B,A32),"-") -> 0 | N32: =+F32/E32 -> 0.78571429 | O32: =+H32/G32 -> 0.78201369 | P32: =K32+L32+M32 -> 0 | Q32: =P32+I32 -> 0 | R32: =Q32/P32 -> #DIV/0! | S32: =MAX(N32,O32) -> 0.78571429
A33: VOY2026COFTN32 | B33: =+IFERROR(VLOOKUP(A33,'Details local delivery'!B:C,2,0),"-") -> 46029 | C33: =B33 -> 46029 | D33: =+IFERROR(VLOOKUP(A33,'Details local delivery'!B:E,4,0),"-") -> 9524TU238 | E33: =VLOOKUP(A33,'Details local delivery'!B:L,11,0) -> 14 | F33: =SUMIFS('Details local delivery'!M:M,'Details local delivery'!G:G,'RECAP Delivery Plan '!A33) -> 9 | G33: =VLOOKUP(A33,'Details local delivery'!B:J,9,0) -> 10230 | H33: =SUMIFS('Details local delivery'!K:K,'Details local delivery'!G:G,'RECAP Delivery Plan '!A33) -> 10000 | I33: =SUMIFS('Details local delivery'!Y:Y,'Details local delivery'!B:B,A:A) -> 0 | J33: =AVERAGEIFS('Details local delivery'!W:W,'Details local delivery'!B:B,A33) -> 1 | K33: =_xlfn.MAXIFS('Details local delivery'!Z:Z,'Details local delivery'!B:B,A33) -> 0 | L33: =_xlfn.MAXIFS('Details local delivery'!AA:AA,'Details local delivery'!B:B,A33) -> 0 | M33: =_xlfn.MAXIFS('Details local delivery'!AB:AB,'Details local delivery'!B:B,A33) -> 0 | N33: =+F33/E33 -> 0.64285714 | O33: =+H33/G33 -> 0.97751711 | P33: =K33+L33+M33 -> 0 | Q33: =P33+I33 -> 0 | R33: =Q33/P33 -> #DIV/0! | S33: =MAX(N33,O33) -> 0.97751711
A34: VOY2026COFTN33 | B34: =+IFERROR(VLOOKUP(A34,'Details local delivery'!B:C,2,0),"-") -> 46029 | C34: =B34 -> 46029 | D34: =+IFERROR(VLOOKUP(A34,'Details local delivery'!B:E,4,0),"-") -> Location | E34: =VLOOKUP(A34,'Details local delivery'!B:L,11,0) -> 0 | F34: =SUMIFS('Details local delivery'!M:M,'Details local delivery'!G:G,'RECAP Delivery Plan '!A34) -> 22 | G34: =VLOOKUP(A34,'Details local delivery'!B:J,9,0) -> 0 | H34: =SUMIFS('Details local delivery'!K:K,'Details local delivery'!G:G,'RECAP Delivery Plan '!A34) -> 0 | I34: =SUMIFS('Details local delivery'!Y:Y,'Details local delivery'!B:B,A:A) -> 0 | J34: =AVERAGEIFS('Details local delivery'!W:W,'Details local delivery'!B:B,A34) -> 1 | K34: =_xlfn.MAXIFS('Details local delivery'!Z:Z,'Details local delivery'!B:B,A34) -> 0 | L34: =_xlfn.MAXIFS('Details local delivery'!AA:AA,'Details local delivery'!B:B,A34) -> 0 | M34: =IFERROR(_xlfn.MAXIFS('Details local delivery'!AB:AB,'Details local delivery'!B:B,A34),"-") -> 0 | N34: =+F34/E34 -> #DIV/0! | O34: =+H34/G34 -> #DIV/0! | P34: =K34+L34+M34 -> 0 | Q34: =P34+I34 -> 0 | R34: =Q34/P34 -> #DIV/0! | S34: =MAX(N34,O34) -> #DIV/0! | U34: change in delivery planning | V34: commande non planifier
A35: VOY2026COFTN34 | B35: =+IFERROR(VLOOKUP(A35,'Details local delivery'!B:C,2,0),"-") -> 46029 | C35: =B35 -> 46029 | D35: =+IFERROR(VLOOKUP(A35,'Details local delivery'!B:E,4,0),"-") -> 4331tu175 | E35: =VLOOKUP(A35,'Details local delivery'!B:L,11,0) -> 14 | F35: =SUMIFS('Details local delivery'!M:M,'Details local delivery'!G:G,'RECAP Delivery Plan '!A35) -> 11 | G35: =VLOOKUP(A35,'Details local delivery'!B:J,9,0) -> 9200 | H35: =SUMIFS('Details local delivery'!K:K,'Details local delivery'!G:G,'RECAP Delivery Plan '!A35) -> 6000 | I35: =SUMIFS('Details local delivery'!Y:Y,'Details local delivery'!B:B,A:A) -> 0 | J35: =AVERAGEIFS('Details local delivery'!W:W,'Details local delivery'!B:B,A35) -> 1 | K35: =_xlfn.MAXIFS('Details local delivery'!Z:Z,'Details local delivery'!B:B,A35) -> 0 | L35: =_xlfn.MAXIFS('Details local delivery'!AA:AA,'Details local delivery'!B:B,A35) -> 0 | M35: =_xlfn.MAXIFS('Details local delivery'!AB:AB,'Details local delivery'!B:B,A35) -> 0 | N35: =+F35/E35 -> 0.78571429 | O35: =+H35/G35 -> 0.65217391 | P35: =K35+L35+M35 -> 0 | Q35: =P35+I35 -> 0 | R35: =Q35/P35 -> #DIV/0! | S35: =MAX(N35,O35) -> 0.78571429 | U35: change in delivery planning | V35: commande non planifier
